<?xml version="1.0" encoding="utf-8"?>
<!-- This URDF was automatically created by SolidWorks to URDF Exporter! Originally created by Stephen Brawner (brawner@gmail.com) 
     Commit Version: 1.6.0-4-g7f85cfe  Build Version: 1.6.7995.38578
     For more information, please see http://wiki.ros.org/sw_urdf_exporter -->
<robot name="right_arm">

   <mujoco>
        <compiler
        meshdir="../meshes/"
        balanceinertia="true"
        discardvisual="false" />
  </mujoco>

  <link name="table_base">
    <inertial>
      <origin
        xyz="0.45001 0.74998 0.42961"
        rpy="0 0 0" />
      <mass
        value="353.69" />
      <inertia
        ixx="90.977"
        ixy="-0.0055919"
        ixz="-0.00060496"
        iyy="36.448"
        iyz="0.0010856"
        izz="111.92" />
    </inertial>
    <visual>
      <origin
        xyz="0 0 0"
        rpy="0 0 0" />
      <geometry>
        <mesh
          filename="../meshes/table_base.STL" />
      </geometry>
      <material
        name="">
        <color
          rgba="1 1 1 1" />
      </material>
    </visual>
    <collision>
      <origin
        xyz="0 0 0"
        rpy="0 0 0" />
      <geometry>
        <mesh
          filename="../meshes/table_base.STL" />
      </geometry>
    </collision>
  </link>

  <link name="right_link0">
    <inertial>
      <origin
        xyz="0.000991862282192705 -0.000192651788556533 0.0195495600981984"
        rpy="0 0 0" />
      <mass
        value="0.51639212234536" />
      <inertia
        ixx="0.000628942697006034"
        ixy="-6.29951814299122E-09"
        ixz="3.21122859626175E-06"
        iyy="0.00086768897455273"
        iyz="2.45009142518561E-07"
        izz="0.00136178777793849" />
    </inertial>
    <visual>
      <origin
        xyz="0 0 0"
        rpy="0 0 0" />
      <geometry>
        <mesh
          filename="../meshes/right_link0.STL" />
      </geometry>
      <material
        name="">
        <color
          rgba="0.847058823529412 0.847058823529412 0.847058823529412 1" />
      </material>
    </visual>
    <collision>
      <origin
        xyz="0 0 0"
        rpy="0 0 0" />
      <geometry>
        <mesh
          filename="../meshes/right_link0.STL" />
      </geometry>
    </collision>
  </link>

  <joint name="r_j0"
    type="revolute">
    <origin
      xyz="0.45 0.20023 0.615"
      rpy="0 0 0" />
    <parent
      link="table_base" />
    <child
      link="right_link0" />
    <axis
      xyz="0 0 1" />
    <limit
      lower="0"
      upper="0"
      effort="0"
      velocity="0" />
  </joint>

  <link name="right_link1">
    <inertial>
      <origin
        xyz="-2.51857531862948E-07 0.00332256500839039 -0.00150902460016494"
        rpy="0 0 0" />
      <mass
        value="15.1346479444998" />
      <inertia
        ixx="0.0443031651788231"
        ixy="-2.81167524079919E-08"
        ixz="-4.05968268990278E-07"
        iyy="0.0430901762109995"
        iyz="1.43719449704963E-05"
        izz="0.0305221713846399" />
    </inertial>
    <visual>
      <origin
        xyz="0 0 0"
        rpy="0 0 0" />
      <geometry>
        <mesh
          filename="../meshes/right_link1.STL" />
      </geometry>
      <material
        name="">
        <color
          rgba="0.847058823529412 0.847058823529412 0.847058823529412 1" />
      </material>
    </visual>
    <collision>
      <origin
        xyz="0 0 0"
        rpy="0 0 0" />
      <geometry>
        <mesh
          filename="../meshes/right_link1.STL" />
      </geometry>
    </collision>
  </link>

  <joint name="r_j1"
    type="revolute">
    <origin
      xyz="0 -0.00022535 0.12015"
      rpy="0 0 0" />
    <parent
      link="right_link0" />
    <child
      link="right_link1" />
    <axis
      xyz="0 0 -1" />
    <limit
      lower="-6.2832"
      upper="6.2832"
      effort="0"
      velocity="0" />
  </joint>

  <link name="right_link2">
    <inertial>
      <origin
        xyz="0.215000100287162 6.43173030112631E-09 -0.143146610069181"
        rpy="0 0 0" />
      <mass
        value="45.8465918633366" />
      <inertia
        ixx="0.1037483140575"
        ixy="-5.87095025796085E-08"
        ixz="2.54282490418091E-07"
        iyy="0.240121009336192"
        iyz="2.15483178628983E-08"
        izz="0.212572501503178" />
    </inertial>
    <visual>
      <origin
        xyz="0 0 0"
        rpy="0 0 0" />
      <geometry>
        <mesh
          filename="../meshes/right_link2.STL" />
      </geometry>
      <material
        name="">
        <color
          rgba="0.847058823529412 0.847058823529412 0.847058823529412 1" />
      </material>
    </visual>
    <collision>
      <origin
        xyz="0 0 0"
        rpy="0 0 0" />
      <geometry>
        <mesh
          filename="../meshes/right_link2.STL" />
      </geometry>
    </collision>
  </link>

  <joint name="r_j2"
    type="revolute">
    <origin
      xyz="0 0 0"
      rpy="1.5708 0 0" />
    <parent
      link="right_link1" />
    <child
      link="right_link2" />
    <axis
      xyz="0 0 1" />
    <limit
      lower="-1.4835"
      upper="4.6251"
      effort="0"
      velocity="0" />
  </joint>

  <link name="right_link3">
    <inertial>
      <origin
        xyz="0.190735496583493 -1.52687675682439E-05 -0.0106365862195597"
        rpy="0 0 0" />
      <mass
        value="18.0534564554839" />
      <inertia
        ixx="0.0197914204709761"
        ixy="6.48612971078311E-07"
        ixz="-0.0162800799758652"
        iyy="0.168630223367361"
        iyz="3.37641397432236E-07"
        izz="0.16527336838242" />
    </inertial>
    <visual>
      <origin
        xyz="0 0 0"
        rpy="0 0 0" />
      <geometry>
        <mesh
          filename="../meshes/right_link3.STL" />
      </geometry>
      <material
        name="">
        <color
          rgba="0.847058823529412 0.847058823529412 0.847058823529412 1" />
      </material>
    </visual>
    <collision>
      <origin
        xyz="0 0 0"
        rpy="0 0 0" />
      <geometry>
        <mesh
          filename="../meshes/right_link3.STL" />
      </geometry>
    </collision>
  </link>

  <joint name="r_j3"
    type="revolute">
    <origin
      xyz="0.43 0 0"
      rpy="0 0 0" />
    <parent
      link="right_link2" />
    <child
      link="right_link3" />
    <axis
      xyz="0 0 1" />
    <limit
      lower="-3.0543"
      upper="3.0543"
      effort="0"
      velocity="0" />
  </joint>

  <link name="right_link4">
    <inertial>
      <origin
        xyz="-1.98734804623957E-06 -0.00595118756440466 0.00267886074216198"
        rpy="0 0 0" />
      <mass
        value="5.53782702890544" />
      <inertia
        ixx="0.00708415707773479"
        ixy="1.83211236326858E-07"
        ixz="-2.36169851102956E-08"
        iyy="0.00516123063669"
        iyz="-0.000397739879929697"
        izz="0.00684324625577804" />
    </inertial>
    <visual>
      <origin
        xyz="0 0 0"
        rpy="0 0 0" />
      <geometry>
        <mesh
          filename="../meshes/right_link4.STL" />
      </geometry>
      <material
        name="">
        <color
          rgba="0.847058823529412 0.847058823529412 0.847058823529412 1" />
      </material>
    </visual>
    <collision>
      <origin
        xyz="0 0 0"
        rpy="0 0 0" />
      <geometry>
        <mesh
          filename="../meshes/right_link4.STL" />
      </geometry>
    </collision>
  </link>

  <joint name="r_j4" type="revolute">
    <origin
      xyz="0.3685 -1.185E-05 -0.114"
      rpy="0 0 0" />
    <parent
      link="right_link3" />
    <child
      link="right_link4" />
    <axis
      xyz="0 0 -1" />
    <limit
      lower="-1.4835"
      upper="4.6251"
      effort="0"
      velocity="0" />
  </joint>
  <link
    name="right_link5">
    <inertial>
      <origin
        xyz="-1.90944871281129E-06 -0.00288907759425724 -0.00234237394169168"
        rpy="0 0 0" />
      <mass
        value="6.33394466548074" />
      <inertia
        ixx="0.012920396120737"
        ixy="-1.08659585918921E-07"
        ixz="5.89055789344623E-09"
        iyy="0.00584529345673906"
        iyz="4.29603782509869E-05"
        izz="0.0126275585433332" />
    </inertial>
    <visual>
      <origin
        xyz="0 0 0"
        rpy="0 0 0" />
      <geometry>
        <mesh
          filename="../meshes/right_link5.STL" />
      </geometry>
      <material
        name="">
        <color
          rgba="0.847058823529412 0.847058823529412 0.847058823529412 1" />
      </material>
    </visual>
    <collision>
      <origin
        xyz="0 0 0"
        rpy="0 0 0" />
      <geometry>
        <mesh
          filename="../meshes/right_link5.STL" />
      </geometry>
    </collision>
  </link>

  <joint name="r_j5" type="revolute">
    <origin
      xyz="0 -0.1135 0"
      rpy="1.5708 0 0" />
    <parent
      link="right_link4" />
    <child
      link="right_link5" />
    <axis
      xyz="0 0 1" />
    <limit
      lower="-6.2832"
      upper="6.2832"
      effort="0"
      velocity="0" />
  </joint>

  <link name="right_link6">
    <inertial>
      <origin
        xyz="2.76523161144571E-05 -1.34854737601515E-05 -0.021245060068734"
        rpy="0 0 0" />
      <mass
        value="1.41689125820954" />
      <inertia
        ixx="0.000713704897956402"
        ixy="-6.91164349011993E-07"
        ixz="-6.36734535410033E-07"
        iyy="0.00072362694039658"
        iyz="1.5890038073839E-06"
        izz="0.00112895600939514" />
    </inertial>
    <visual>
      <origin
        xyz="0 0 0"
        rpy="0 0 0" />
      <geometry>
        <mesh
          filename="../meshes/right_link6.STL" />
      </geometry>
      <material
        name="">
        <color
          rgba="0.847058823529412 0.847058823529412 0.847058823529412 1" />
      </material>
    </visual>
    <collision>
      <origin
        xyz="0 0 0"
        rpy="0 0 0" />
      <geometry>
        <mesh
          filename="../meshes/right_link6.STL" />
      </geometry>
    </collision>
  </link>

  <joint name="r_j6" type="revolute">
    <origin
      xyz="0 0.107 0"
      rpy="-1.5708 0 0" />
    <parent
      link="right_link5" />
    <child
      link="right_link6" />
    <axis
      xyz="0 0 1" />
    <limit
      lower="-6.2832"
      upper="6.2832"
      effort="0"
      velocity="0" />
  </joint>

  <link name="force_sensor_link">
    <inertial>
      <origin
        xyz="-0.00038657 0.00017956 -0.02055"
        rpy="0 0 0" />
      <mass
        value="0.12592" />
      <inertia
        ixx="5.6139E-05"
        ixy="4.6333E-07"
        ixz="-3.1627E-08"
        iyy="5.5177E-05"
        iyz="-1.4175E-07"
        izz="9.499E-05" />
    </inertial>
    <visual>
      <origin
        xyz="0 0 0"
        rpy="0 0 0" />
      <geometry>
        <mesh
          filename="../meshes/force_sensor_link.STL" />
      </geometry>
      <material
        name="">
        <color
          rgba="1 1 1 1" />
      </material>
    </visual>
    <collision>
      <origin
        xyz="0 0 0"
        rpy="0 0 0" />
      <geometry>
        <mesh
          filename="../meshes/force_sensor_link.STL" />
      </geometry>
    </collision>
  </link>

  <joint name="r_f1" type="fixed">
    <origin
      xyz="0.00044323 -0.00044323 0.0395"
      rpy="0 0 0" />
    <parent
      link="right_link6" />
    <child
      link="force_sensor_link" />
    <axis
      xyz="0 0 0" />
  </joint>

  <link name="tool_body">
    <inertial>
      <origin
        xyz="0.0030549 4.2661E-07 0.047026"
        rpy="0 0 0" />
      <mass
        value="0.31958" />
      <inertia
        ixx="0.0011856"
        ixy="-1.0021E-07"
        ixz="2.5315E-07"
        iyy="0.00041875"
        iyz="-7.8268E-10"
        izz="0.0014705" />
    </inertial>
    <visual>
      <origin
        xyz="0 0 0"
        rpy="0 0 0" />
      <geometry>
        <mesh
          filename="../meshes/tool_body.STL" />
      </geometry>
      <material
        name="">
        <color
          rgba="0.74902 0.74902 0.74902 1" />
      </material>
    </visual>
    <collision>
      <origin
        xyz="0 0 0"
        rpy="0 0 0" />
      <geometry>
        <mesh
          filename="../meshes/tool_body.STL" />
      </geometry>
    </collision>
  </link>

  <joint name="r_f2" type="revolute">
    <origin
      xyz="-0.00044323 0.00044323 0.013"
      rpy="0 0 0" />
    <parent
      link="force_sensor_link" />
    <child
      link="tool_body" />
    <axis
      xyz="0 0 -1" />
    <limit
      lower="0"
      upper="0"
      effort="0"
      velocity="0" />
  </joint>

  <link name="screw_gear">
    <inertial>
      <origin
        xyz="-0.018422 -0.0011551 0.0012466"
        rpy="0 0 0" />
      <mass
        value="0.4637" />
      <inertia
        ixx="0.0010994"
        ixy="2.3876E-05"
        ixz="1.4588E-06"
        iyy="0.00058941"
        iyz="2.5853E-07"
        izz="0.0016815" />
    </inertial>
    <visual>
      <origin
        xyz="0 0 0"
        rpy="0 0 0" />
      <geometry>
        <mesh
          filename="../meshes/screw_gear.STL" />
      </geometry>
      <material
        name="">
        <color
          rgba="0.63922 0.63922 0.66275 1" />
      </material>
    </visual>
    <collision>
      <origin
        xyz="0 0 0"
        rpy="0 0 0" />
      <geometry>
        <mesh
          filename="../meshes/screw_gear.STL" />
      </geometry>
    </collision>
  </link>

  <joint name="r_c1" type="continuous">
    <origin
      xyz="-0.0785 0 0.0644"
      rpy="3.1416 0 3.1416" />
    <parent
      link="tool_body" />
    <child
      link="screw_gear" />
    <axis
      xyz="0 0 -1" />
  </joint>

  <link name="side_left">
    <inertial>
      <origin
        xyz="-1.9154E-10 5.5893E-12 0.00045008"
        rpy="0 0 0" />
      <mass
        value="0.0043012" />
      <inertia
        ixx="1.3074E-07"
        ixy="6.2645E-15"
        ixz="4.2165E-16"
        iyy="3.1828E-07"
        iyz="6.4925E-16"
        izz="2.6659E-07" />
    </inertial>
    <visual>
      <origin
        xyz="0 0 0"
        rpy="0 0 0" />
      <geometry>
        <mesh
          filename="../meshes/side_left.STL" />
      </geometry>
      <material
        name="">
        <color
          rgba="0.74902 0.74902 0.74902 1" />
      </material>
    </visual>
    <collision>
      <origin
        xyz="0 0 0"
        rpy="0 0 0" />
      <geometry>
        <mesh
          filename="../meshes/side_left.STL" />
      </geometry>
    </collision>
  </link>

  <joint name="r_p1" type="prismatic">
    <origin
      xyz="0.0012847 -0.026778 0.0036"
      rpy="-1.5708 0 -3.0937" />
    <parent
      link="screw_gear" />
    <child
      link="side_left" />
    <axis
      xyz="0 0 -1" />
    <limit
      lower="-0.01"
      upper="0.005"
      effort="0"
      velocity="0" />
  </joint>

  <link name="right_side">
    <inertial>
      <origin
        xyz="2.2426E-05 3.1396E-05 2.1095E-05"
        rpy="0 0 0" />
      <mass
        value="0.0042532" />
      <inertia
        ixx="3.0118E-07"
        ixy="-7.0175E-15"
        ixz="2.9195E-17"
        iyy="1.1553E-07"
        iyz="1.3439E-16"
        izz="2.6427E-07" />
    </inertial>
    <visual>
      <origin
        xyz="0 0 0"
        rpy="0 0 0" />
      <geometry>
        <mesh
          filename="../meshes/right_side.STL" />
      </geometry>
      <material
        name="">
        <color
          rgba="0.74902 0.74902 0.74902 1" />
      </material>
    </visual>
    <collision>
      <origin
        xyz="0 0 0"
        rpy="0 0 0" />
      <geometry>
        <mesh
          filename="../meshes/right_side.STL" />
      </geometry>
    </collision>
  </link>

  <joint name="r_p2" type="prismatic">
    <origin
      xyz="-0.0012847 0.026778 0.0036"
      rpy="1.6187 -1.5708 0" />
    <parent
      link="screw_gear" />
    <child
      link="right_side" />
    <axis
      xyz="0 0 1" />
    <limit
      lower="-0.01"
      upper="0.005"
      effort="0"
      velocity="0" />
  </joint>




  <link name="left_arm_site">
    <inertial>
      <origin
        xyz="0 0 0"
        rpy="0 0 0" />
      <mass
        value="0.51639212234536" />
      <inertia
        ixx="0.000628942697006034"
        ixy="-6.29951814299122E-09"
        ixz="3.21122859626175E-06"
        iyy="0.00086768897455273"
        iyz="2.45009142518561E-07"
        izz="0.00136178777793849" />
    </inertial>
    <visual>
      <origin
        xyz="0 0 0"
        rpy="0 0 0" />
      <geometry>
        <mesh
          filename="../meshes/left_arm_site.STL" />
      </geometry>
      <material
        name="">
        <color
          rgba="1 1 1 1" />
      </material>
    </visual>
    <collision>
      <origin
        xyz="0 0 0"
        rpy="0 0 0" />
      <geometry>
        <mesh
          filename="../meshes/left_arm_site.STL" />
      </geometry>
    </collision>
  </link>

 <joint name="l_f0" type="revolute">
    <origin
      xyz="1.1687 0.0937 0.59486"
      rpy="-3.1416 0.047938 0" />
    <parent
      link="table_base" />
    <child
      link="left_arm_site" />
    <axis
      xyz="-0.04792 0 -0.99885" />
    <limit
      lower="0"
      upper="0"
      effort="0"
      velocity="0" />
  </joint>
</robot>