<mujoco>

  <worldbody>

    <body name="table_base" pos="0 0 0">
      <geom type="mesh"  rgba="1 1 1 1" mesh="table_base"/>
<!--      <geom type="mesh" rgba="1 1 1 1" mesh="table_base"/>-->

      <body name="left_arm_site" pos="0.475 1.3 0.615">
        <site name="left_arm_site_visual" pos="0 0 0" size="0.01"/>
        <include file="dual_left_arm.xml"/>
      </body>

        <body name="right_link0" pos="0.45 0.20023 0.615">
          <inertial pos="0.000991862 -0.000192652 0.0195496" quat="0.000163964 0.708654 0.000186568 0.705556" mass="0.516392" diaginertia="0.0013618 0.000867689 0.000628929"/>
    <!--      <joint name="r_j0" pos="0 0 0" axis="0 0 1"/>-->
          <geom type="mesh" rgba="0.847059 0.847059 0.847059 1" mesh="right_link0"/>
<!--          <geom type="mesh" rgba="0.847059 0.847059 0.847059 1" mesh="right_link0"/>-->

          <body name="right_link1" pos="0 -0.00022535 0.12015">
            <inertial pos="-2.51858e-07 0.00332257 -0.00150902" quat="1 0.000571766 1.47348e-05 -1.1773e-05" mass="15.1346" diaginertia="0.0443032 0.0430902 0.0305222"/>
            <joint name="r_j1" pos="0 0 0" axis="0 0 1" range="-6.2832 6.2832" />
            <geom type="mesh" rgba="0.847059 0.847059 0.847059 1" mesh="right_link1"/>
<!--            <geom type="mesh" rgba="0.847059 0.847059 0.847059 1" mesh="right_link1"/>-->

            <body name="right_link2" quat="0.707105 0.707108 0 0">
              <inertial pos="0.215 6.43173e-09 -0.143147" quat="0.499999 0.500001 0.500001 0.499999" mass="45.8466" diaginertia="0.240121 0.212573 0.103748"/>
              <joint name="r_j2" pos="0 0 0" axis="0 0 1" range="-1.4835 4.6251" />
              <geom type="mesh" rgba="0.847059 0.847059 0.847059 1" mesh="right_link2"/>
<!--              <geom type="mesh" rgba="0.847059 0.847059 0.847059 1" mesh="right_link2"/>-->

              <body name="right_link3" pos="0.43 0 0">
                <inertial pos="0.190735 -1.52688e-05 -0.0106366" quat="0.526708 0.471775 0.471693 0.526795" mass="18.0535" diaginertia="0.16863 0.167073 0.0179919"/>
                <joint name="r_j3" pos="0 0 0" axis="0 0 1" range="-3.0543 3.0543" />
                <geom type="mesh" rgba="0.847059 0.847059 0.847059 1" mesh="right_link3"/>
<!--                <geom type="mesh" rgba="0.847059 0.847059 0.847059 1" mesh="right_link3"/>-->

                <body name="right_link4" pos="0.3685 -1.185e-05 -0.114">
                  <inertial pos="-1.98735e-06 -0.00595119 0.00267886" quat="0.624865 0.780733 0.000189645 -9.65373e-05" mass="5.53783" diaginertia="0.00708416 0.00693256 0.00507192"/>
                  <joint name="r_j4" pos="0 0 0" axis="0 0 1" range="-1.4835 4.6251"/>
                  <geom type="mesh"  rgba="0.847059 0.847059 0.847059 1" mesh="right_link4"/>
<!--                  <geom type="mesh" rgba="0.847059 0.847059 0.847059 1" mesh="right_link4"/>-->

                  <body name="right_link5" pos="0 -0.1135 0" quat="0.707105 0.707108 0 0">
                    <inertial pos="-1.90945e-06 -0.00288908 -0.00234237" quat="0.709343 0.704864 -1.17153e-05 8.92331e-07" mass="6.33394" diaginertia="0.0129204 0.0126278 0.00584502"/>
                    <joint name="r_j5" pos="0 0 0" axis="0 0 1" range="-6.2832 6.2832" />
                    <geom type="mesh"  rgba="0.847059 0.847059 0.847059 1" mesh="right_link5"/>
<!--                    <geom type="mesh" rgba="0.847059 0.847059 0.847059 1" mesh="right_link5"/>-->

                    <body name="right_link6" pos="0 0.107 0" quat="0.707105 -0.707108 0 0">
                      <inertial pos="3.00198e-05 -3.39048e-05 -0.0179645" quat="-0.00507871 0.706022 0.0122502 0.708065" mass="1.54281" diaginertia="0.00122398 0.00096562 0.000956681"/>
                      <joint name="r_j6" pos="0 0 0" axis="0 0 1" range="-6.2832 6.2832" />
<!--                      <geom type="mesh" contype="0" conaffinity="0" group="1" density="0" rgba="0.847059 0.847059 0.847059 1" mesh="right_link6"/>-->
                      <geom type="mesh" rgba="0.847059 0.847059 0.847059 1" mesh="right_link6"/>

                      <body name="r_sensor">
                        <geom pos="0.00044323 -0.00044323 0.0395" type="mesh" rgba="1 1 1 1" mesh="force_sensor_link"/>
<!--                        <site name="r_sensor_site" pos="0.00044323 -0.00044323 0.395" size="0.01"/>-->


                        <body name="tool_body" pos="0 0 0.0525">
                          <site name="r_sensor_site" pos="0.00044323 -0.00044323 -0.013" size="0.01"/>
                          <inertial pos="0.0030549 4.2661e-07 0.047026" quat="0.500255 0.500189 -0.49981 0.499745" mass="0.31958" diaginertia="0.0014705 0.0011856 0.00041875"/>
                          <geom type="mesh" rgba="0.74902 0.74902 0.74902 1" contype="0" conaffinity="0" mesh="tool_body"/>
                          <site name="screwing_frame" pos="-0.0785 0 0.0644" quat="1.34924e-11 -3.67321e-06 1 -3.67321e-06" size="0.01"/>

                          <body name="screw_gear" pos="-0.0785 0 0.0644" quat="1.34924e-11 -3.67321e-06 1 -3.67321e-06">
                            <inertial pos="-0.018422 -0.0011551 0.0012466" quat="0.488884 0.512105 -0.487505 0.51096" mass="0.4637" diaginertia="0.0016815 0.00110051 0.000588295"/>
                            <joint name="r_c1" pos="0 0 0" axis="0 0 -1"  type="hinge" range="-100 100"/>
                            <geom type="mesh"  rgba="0.63922 0.63922 0.66275 1" contype="0" conaffinity="0" mesh="screw_gear"/>

<!--                            上述两个geom 因为凸包太复杂，直接设置为不参与碰撞，因为mujuco是基于凸包计算碰撞的-->

                            <body name="peg" pos="0 0 0">
                              <geom name="peg_pole" pos="0.0 0.0 -0.02" type="cylinder" size="0.01 0.04" contype='1' conaffinity='1' condim='4'  margin="0" solref=".02 1" solimp=".8 .9 .001" rgba="1 0 0 1"/>
                            </body>

                            <body name="side_left" pos="0.0012847 -0.026778 0.0036" quat="0.016931 -0.016931 0.706905 -0.706903">
                              <inertial pos="-1.9154e-10 5.5893e-12 0.00045008" quat="0.5 0.5 0.5 0.5" mass="0.0043012" diaginertia="3.1828e-07 2.6659e-07 1.3074e-07"/>
<!--                              <joint name="r_p1" pos="0 0 0" axis="0 0 -1" damping="3" type="slide" range="0.0 0.01" />-->
                              <geom type="mesh" rgba="0.74902 0.74902 0.74902 1" mesh="side_left"/>
  <!--                            <geom type="mesh" rgba="0.74902 0.74902 0.74902 1" mesh="side_left"/>-->
                            </body>
                            <body name="right_side" pos="-0.0012847 0.026778 0.0036" quat="0.51183 -0.487885 -0.511829 -0.487883">
                              <inertial pos="2.2426e-05 3.1396e-05 2.1095e-05" quat="0.707107 0.707107 0 0" mass="0.0042532" diaginertia="3.0118e-07 2.6427e-07 1.1553e-07"/>
<!--                              <joint name="r_p2" pos="0 0 0" axis="0 0 -1" damping="3" type="slide" range="0.0 0.01 " />-->
                              <geom type="mesh" rgba="0.74902 0.74902 0.74902 1" mesh="right_side"/>
  <!--                            <geom type="mesh" rgba="0.74902 0.74902 0.74902 1" mesh="right_side"/>-->
                            </body>
                          </body>
                        </body>
                      </body>
                    </body>
                  </body>
                </body>
              </body>
            </body>
          </body>
        </body>
    </body>

    <body name="hole" pos="0.35 0.65 0.606">
<!--            <geom name='hole_base_geom' type="box" size="0.575 0.575 0.015" pos="0.5 0 -0.025" rgba="1 0 0 1"/>-->
            <geom name='hole_geom_2' type="box" pos="0 0 0" size="0.1 0.1 0.008" quat = "0 0 1 0"  rgba = "0 1 0 1" contype="1" conaffinity="1"/>
    </body>
  </worldbody>

     <!--Contacts-->
    <contact>
        <exclude body1="gripper_body" body2="left_gripper"/>
		<exclude body1="gripper_body" body2="right_gripper"/>
		<exclude body1="tool_body" body2="screw_gear"/>
        <exclude body1="tool_body" body2="side_left"/>
        <exclude body1="tool_body" body2="right_side"/>
        <exclude body1="screw_gear" body2="side_left"/>
		<exclude body1="screw_gear" body2="right_side"/>
<!--		<exclude body1="wrist_1_link" body2="wrist_2_link"/>-->
<!--        <exclude body1="wrist_2_link" body2="wrist_3_link"/>-->
        <!--exclude body1="ee_link" body2="wrist_3_link"/-->
    </contact>


</mujoco>