<!--xyz顺序的欧拉角-->

<mujoco>


    <body name="left_base" pos="0 0 0">
<!--    <geom type="mesh" contype="0" conaffinity="0" group="1" density="0" rgba="0.84706 0.84706 0.84706 1" mesh="left_base"/>-->
    <geom type="mesh" rgba="0.84706 0.84706 0.84706 1" mesh="left_base"/>

        <body name="left_link1" pos="0 -0.00022535 0.12015">
          <inertial pos="-2.5186e-07 0.0033226 -0.001509" quat="1 0.000571768 1.47349e-05 -1.17729e-05" mass="15.135" diaginertia="0.044303 0.04309 0.030522"/>
          <joint name="l_j1" pos="0 0 0" axis="0 0 1" range="-6.2832 6.2832" />
<!--          <geom type="mesh" contype="0" conaffinity="0" group="1" density="0" rgba="0.84706 0.84706 0.84706 1" mesh="left_link1"/>-->
          <geom type="mesh" rgba="0.84706 0.84706 0.84706 1" mesh="left_link1"/>

          <body name="left_link2" quat="0.707105 0.707108 0 0">
            <inertial pos="0.215 6.4317e-09 -0.14315" quat="0.499999 0.500001 0.500001 0.499999" mass="45.847" diaginertia="0.24012 0.21257 0.10375"/>
            <joint name="l_j2" pos="0 0 0" axis="0 0 1" range="-1.4835 4.6251" />
<!--            <geom type="mesh" contype="0" conaffinity="0" group="1" density="0" rgba="0.84706 0.84706 0.84706 1" mesh="left_link2"/>-->
            <geom type="mesh" rgba="0.84706 0.84706 0.84706 1" mesh="left_link2"/>

            <body name="left_link3" pos="0.43 0 0">
              <inertial pos="0.19074 -1.5269e-05 -0.010637" quat="0.526708 0.471775 0.471692 0.526795" mass="18.053" diaginertia="0.16863 0.16707 0.0179914"/>
              <joint name="l_j3" pos="0 0 0" axis="0 0 1" range="-3.0543 3.0543" />
<!--              <geom type="mesh" contype="0" conaffinity="0" group="1" density="0" rgba="0.84706 0.84706 0.84706 1" mesh="left_link3"/>-->
              <geom type="mesh" rgba="0.84706 0.84706 0.84706 1" mesh="left_link3"/>

              <body name="left_link4" pos="0.3685 -1.185e-05 -0.114">
                <inertial pos="-1.9873e-06 -0.0059512 0.0026789" quat="0.624864 0.780734 0.000189549 -9.64629e-05" mass="5.5378" diaginertia="0.0070842 0.00693251 0.00507189"/>
                <joint name="l_j4" pos="0 0 0" axis="0 0 1" range="-1.4835 4.6251" />
<!--                <geom type="mesh" contype="0" conaffinity="0" group="1" density="0" rgba="0.84706 0.84706 0.84706 1" mesh="left_link4"/>-->
                <geom type="mesh" rgba="0.84706 0.84706 0.84706 1" mesh="left_link4"/>

                <body name="left_link5" pos="0 -0.1135 0" quat="0.707105 0.707108 0 0">
                  <inertial pos="-1.9094e-06 -0.0028891 -0.0023424" quat="0.709342 0.704864 -1.17337e-05 9.10219e-07" mass="6.3339" diaginertia="0.01292 0.0126283 0.00584503"/>
                  <joint name="l_j5" pos="0 0 0" axis="0 0 1" range="-6.2832 6.2832" />
<!--                  <geom type="mesh" contype="0" conaffinity="0" group="1" density="0" rgba="0.84706 0.84706 0.84706 1" mesh="left_link5"/>-->
                  <geom type="mesh" rgba="0.84706 0.84706 0.84706 1" mesh="left_link5"/>

                  <body name="left_link6" pos="0 0.107 0" quat="0.707105 -0.707108 0 0">
                    <inertial pos="0.0174462 -0.0173981 -0.00448812" quat="-0.375086 0.689592 0.155164 0.599747" mass="2.14716" diaginertia="0.00249435 0.00219822 0.00149465"/>
                    <joint name="l_j6" pos="0 0 0" axis="0 0 1" range="-6.2832 6.2832" />
                    <geom type="mesh" rgba="0.84706 0.84706 0.84706 1" mesh="left_link6"/>

                    <body name="l_sensor">
                      <geom pos="0 0 0.0495" type="mesh" rgba="1 1 1 1" mesh="left_force_sensor"/>
<!--                      <site name="l_sensor_site" pos="0 0 0.0495"  size="0.01"/>-->


                      <body name="gripper_body" pos="0 0 0.0495" quat="0.923879 0 0 -0.382684">
                        <site name="l_sensor_site" pos="0 0 0"  quat="0.923879 0 0 0.382684" size="0.01"/>
                        <inertial pos="2.2506e-05 -0.00012911 0.050935" quat="0.704281 0.00219157 -0.00217151 0.709914" mass="0.34315" diaginertia="0.000278993 0.00027737 0.000203337"/>
                        <geom type="mesh" rgba="1 1 1 1" mesh="gripper_body"/>
                        <site name="grasping_frame" pos="0 0 0.183" quat="0.7071 0 0 0.7071" size="0.01"/>

                          <body name="left_gripper" pos="0 -0.025 0.14678" quat="0.499998 0.5 -0.5 0.500002">
                            <inertial pos="-0.029434 0.0072389 -0.0025796" quat="0.626456 0.48589 0.248433 0.556547" mass="0.013412" diaginertia="6.34101e-06 5.60077e-06 1.55442e-06"/>
                            <joint name="l_p1" pos="0 0 0" axis="0 0 -1" type="slide" range="0.0 0.025" />
    <!--                        <geom type="mesh" contype="0" conaffinity="0" group="1" density="0" rgba="1 0.94902 0.9098 1" mesh="left_gripper"/>-->
                            <geom type="mesh" rgba="1 0.94902 0.9098 1" mesh="left_gripper"/>
                          </body>
                          <body name="right_gripper" pos="0 0.025 0.14678" quat="0.707105 0.707108 0 0">
                            <inertial pos="0.0072589 -0.029434 0.0025796" quat="0.83651 0.519244 0.167907 0.0494332" mass="0.013412" diaginertia="6.34101e-06 5.60077e-06 1.55442e-06"/>
                            <joint name="l_p2" pos="0 0 0" axis="0 0 1" type="slide" range="0.0 0.025 " />
    <!--                        <geom type="mesh" contype="0" conaffinity="0" group="1" density="0" rgba="1 0.94902 0.9098 1" mesh="right_gripper"/>-->
                            <geom type="mesh" rgba="1 0.94902 0.9098 1" mesh="right_gripper"/>
                          </body>

                      </body>
                    </body>
                  </body>
                </body>
              </body>
            </body>
          </body>
        </body>
    </body>

</mujoco>

